data/_example_Kenney-Jam-2022_105210-20220928.csv
game_title,author,number_of_ratings,overall_rank,overall_score,overall_raw_score,theme_rank,theme_score,theme_raw_score,presentation_visuals_rank,presentation_visuals_score,presentation_visuals_raw_score,concept_gameplay_rank,concept_gameplay_score,concept_gameplay_raw_score
The Foody Snake,sagar.redkar.1999, 66,#1,4.520,4.520,#2,4.606,4.606,#3,4.500,4.500,#4,4.455,4.455
Conflagrow,"Priyankaj, Tamasik", 88,#2,4.519,4.519,#3,4.511,4.511,#2,4.580,4.580,#3,4.466,4.466
Feed the Horde,Jules5, 16,#3,4.354,4.354,#14,4.313,4.313,#9,4.250,4.250,#2,4.500,4.500
Castle Blitz,MrRan, 27,#4,4.333,4.333,#29,4.000,4.000,#1,4.630,4.630,#6,4.370,4.370
Zenless Garden,CanisBorealis, 16,#5,4.313,4.313,#5,4.438,4.438,#32,3.938,3.938,#1,4.563,4.563
KINOKO,David, 20,#6,4.250,4.250,#4,4.450,4.450,#11,4.200,4.200,#15,4.100,4.100
Terraforma,BenjaTK, 140,#7,4.226,4.226,#25,4.086,4.086,#4,4.479,4.479,#13,4.114,4.114
Animal Merge,miclop, 14,#8,4.214,4.214,#8,4.429,4.429,#18,4.071,4.071,#11,4.143,4.143
Golfinity,Spratley, 57,#9,4.158,4.158,#13,4.316,4.316,#36,3.912,3.912,#9,4.246,4.246
HexaForest,Cyanegy, 20,#10,4.150,4.150,#11,4.350,4.350,#14,4.100,4.100,#22,4.000,4.000
Growing Monster,flavedogame, 9,#11,4.148,4.148,#1,4.667,4.667,#73,3.556,3.556,#10,4.222,4.222
Thingies Tower,"Alan Kilby, Ulric Debaert", 9,#11,4.148,4.148,#29,4.000,4.000,#23,4.000,4.000,#5,4.444,4.444
Killer Vortex,"Knifepoint Games, Trashcan Studios, BRUNOTEMC, Dillyo, He4thriley, PieroTechnical, Dr Codex, HakoDev", 23,#13,4.116,4.116,#7,4.435,4.435,#15,4.087,4.087,#30,3.826,3.826
Branching Out,Little Martian, 48,#14,4.090,4.090,#5,4.438,4.438,#10,4.208,4.208,#53,3.625,3.625
Kenneymari,"zoped, tfx, Moose, hiijcat", 38,#15,4.070,4.070,#10,4.368,4.368,#42,3.842,3.842,#22,4.000,4.000
Space Swarm,Aniol92, 13,#16,4.051,4.051,#53,3.769,3.769,#17,4.077,4.077,#8,4.308,4.308
Let There Be Color,tfwa.games, 21,#17,4.016,4.016,#36,3.905,3.905,#23,4.000,4.000,#11,4.143,4.143
Mushroom Madness,MattBann, 12,#18,4.000,4.000,#12,4.333,4.333,#43,3.833,3.833,#29,3.833,3.833
BlockSprawl,Tripgoodwill, 14,#19,3.976,3.976,#18,4.214,4.214,#106,3.357,3.357,#7,4.357,4.357
Tree Truck,anwpecirotan, 12,#20,3.944,3.944,#29,4.000,4.000,#16,4.083,4.083,#40,3.750,3.750
The Great Tree,dandeliondino, 15,#21,3.933,3.933,#59,3.667,3.667,#8,4.267,4.267,#25,3.867,3.867
Truck Pet Simulator 👁️👄👁️,valorware, 57,#22,3.918,3.918,#19,4.175,4.175,#44,3.807,3.807,#37,3.772,3.772
Denzel's Growth Lab,Nat, 26,#23,3.910,3.910,#21,4.115,4.115,#70,3.577,3.577,#21,4.038,4.038
Grow Thy Hoe!,"lvlcn, Robby-the-paladin", 10,#24,3.900,3.900,#23,4.100,4.100,#84,3.500,3.500,#15,4.100,4.100
Gary is Growing Up!,Asdonaur, 36,#25,3.898,3.898,#17,4.250,4.250,#29,3.972,3.972,#66,3.472,3.472
CarniGrow,"FryMeALiver, Necro8", 19,#26,3.877,3.877,#27,4.053,4.053,#19,4.053,4.053,#61,3.526,3.526
Attack before they grow!,Yumeji, 17,#27,3.863,3.863,#94,3.412,3.412,#13,4.118,4.118,#18,4.059,4.059
planetarium,bucketfish, 20,#28,3.850,3.850,#29,4.000,4.000,#38,3.900,3.900,#51,3.650,3.650
The Forest Sage,microteller, 15,#29,3.844,3.844,#26,4.067,4.067,#65,3.600,3.600,#25,3.867,3.867
Firefighting aircraft,Inidvy, 11,#30,3.818,3.818,#65,3.636,3.636,#23,4.000,4.000,#32,3.818,3.818
Slime me up!,Indierama, 24,#31,3.806,3.806,#20,4.167,4.167,#76,3.542,3.542,#44,3.708,3.708
Kn.y.J type Parasite,casualBystander, 22,#32,3.803,3.803,#39,3.864,3.864,#30,3.955,3.955,#56,3.591,3.591
Anything Growth,NiceBug Games, 13,#33,3.795,3.795,#15,4.308,4.308,#118,3.231,3.231,#28,3.846,3.846
The Growing Mountain,Luis Felipe Patrocinio, 11,#34,3.758,3.758,#85,3.455,3.455,#6,4.455,4.455,#76,3.364,3.364
Spiral,HackTrout, 15,#35,3.756,3.756,#77,3.533,3.533,#5,4.467,4.467,#89,3.267,3.267
Don't Lose Your Head! (Improved Post-Game Jam Edition),SkellySoft, 9,#36,3.741,3.741,#51,3.778,3.778,#54,3.667,3.667,#36,3.778,3.778
Blocky Tower,stmn, 10,#37,3.733,3.733,#46,3.800,3.800,#65,3.600,3.600,#35,3.800,3.800
Bon appetit,CrazyKrakenStudio, 20,#38,3.717,3.717,#40,3.850,3.850,#12,4.150,4.150,#108,3.150,3.150
Mushroom Rushroom,weirdybeardyman, 16,#39,3.708,3.708,#38,3.875,3.875,#84,3.500,3.500,#40,3.750,3.750
Guild Of The Snake,Ginger Gamer, 10,#40,3.700,3.700,#46,3.800,3.800,#65,3.600,3.600,#46,3.700,3.700
Growy Gal,thelethalkind, 22,#41,3.697,3.697,#44,3.818,3.818,#40,3.864,3.864,#75,3.409,3.409
Sky's The Limit,Bronto Games, 26,#42,3.679,3.679,#41,3.846,3.846,#63,3.615,3.615,#57,3.577,3.577
All Bricked Up,Skarrion, 11,#43,3.667,3.667,#65,3.636,3.636,#37,3.909,3.909,#68,3.455,3.455
Melon Splatman,Schu, 24,#43,3.667,3.667,#74,3.542,3.542,#52,3.708,3.708,#40,3.750,3.750
Shaky Bricks™,Rai4u, 10,#45,3.633,3.633,#37,3.900,3.900,#113,3.300,3.300,#46,3.700,3.700
Captain TrashDog and His Riverboat Quest to Clean the Canal,TheTallMatt, 45,#46,3.630,3.630,#117,3.133,3.133,#34,3.933,3.933,#31,3.822,3.822
Tower,S1L3nCe, 19,#47,3.614,3.614,#27,4.053,4.053,#170,2.737,2.737,#19,4.053,4.053
Three Wizards In A Trenchcoat,HOPL, 22,#48,3.606,3.606,#111,3.273,3.273,#91,3.455,3.455,#17,4.091,4.091
it sproots,Stridden, 11,#49,3.606,3.606,#44,3.818,3.818,#50,3.727,3.727,#88,3.273,3.273
MASH RUN,tnk, 15,#50,3.600,3.600,#96,3.400,3.400,#78,3.533,3.533,#25,3.867,3.867
Terrabbit,kanebo, 28,#51,3.595,3.595,#89,3.429,3.429,#39,3.893,3.893,#67,3.464,3.464
A Very Plane Game,tracfacsam, 27,#52,3.593,3.593,#58,3.704,3.704,#116,3.259,3.259,#34,3.815,3.815
Mushroom jungle,CursedPopcorn, 12,#53,3.583,3.583,#34,3.917,3.917,#69,3.583,3.583,#90,3.250,3.250
Growkoban,ProdigalSon Games, 27,#54,3.580,3.580,#130,3.037,3.037,#68,3.593,3.593,#14,4.111,4.111
Civilization,Lethian, 19,#55,3.579,3.579,#70,3.579,3.579,#23,4.000,4.000,#107,3.158,3.158
Raceagon,Xabi Goenaga, 22,#56,3.576,3.576,#95,3.409,3.409,#60,3.636,3.636,#49,3.682,3.682
Let It Burn,Sivk, 14,#57,3.571,3.571,#49,3.786,3.786,#71,3.571,3.571,#77,3.357,3.357
Hungry Cyclops,gobo, 21,#58,3.540,3.540,#16,4.286,4.286,#127,3.143,3.143,#97,3.190,3.190
Jup Jup,Luu Thanh Dat, 8,#59,3.536,3.750,#92,3.418,3.625,#47,3.771,4.000,#72,3.418,3.625
Traffic Troubles,SodiumNickel, 25,#60,3.533,3.533,#46,3.800,3.800,#133,3.040,3.040,#39,3.760,3.760
Grow your corn!,Joopino, 10,#60,3.533,3.533,#9,4.400,4.400,#122,3.200,3.200,#117,3.000,3.000
Super Hat Man,WiddleBlaster, 7,#62,3.528,4.000,#62,3.654,4.143,#57,3.654,4.143,#86,3.276,3.714
Moleculation - Kenney Jam 2022,Felipe Martelo, 9,#63,3.519,3.519,#72,3.556,3.556,#73,3.556,3.556,#69,3.444,3.444
Cosmic Garden,QuietBenchZen, 9,#64,3.519,3.519,#59,3.667,3.667,#54,3.667,3.667,#93,3.222,3.222
AnimalCircle,JiaoshouMa, 29,#65,3.506,3.506,#78,3.517,3.517,#109,3.345,3.345,#50,3.655,3.655
Fish With A Gun,Shiiro10Psi, 18,#66,3.500,3.500,#72,3.556,3.556,#104,3.389,3.389,#58,3.556,3.556
"One Fish, Two Fish","EliWii123, yaminoodle", 19,#67,3.491,3.491,#70,3.579,3.579,#53,3.684,3.684,#96,3.211,3.211
Resurrect And Conquer,"Herweins, Steve Base Music", 15,#68,3.489,3.489,#142,2.867,2.867,#23,4.000,4.000,#54,3.600,3.600
Attack on the Growing Titans,Ratweeb, 13,#69,3.487,3.487,#68,3.615,3.615,#130,3.077,3.077,#38,3.769,3.769
Speed Road,SquallyPillow, 22,#70,3.485,3.485,#124,3.091,3.091,#75,3.545,3.545,#32,3.818,3.818
Space to Grow,Scrunge1104, 11,#71,3.485,3.485,#35,3.909,3.909,#60,3.636,3.636,#129,2.909,2.909
Growing Gilbert,StreetmanGames, 14,#72,3.476,3.476,#29,4.000,4.000,#97,3.429,3.429,#117,3.000,3.000
Sugarflash (Kenney Jam 2022),TLohProducts, 22,#73,3.470,3.470,#128,3.045,3.045,#20,4.045,4.045,#81,3.318,3.318
Ungrow,Erkberg, 26,#74,3.462,3.462,#80,3.500,3.500,#105,3.385,3.385,#62,3.500,3.500
Graveyard shift,WhySoup, 16,#75,3.458,3.458,#137,2.938,2.938,#32,3.938,3.938,#62,3.500,3.500
How I Ate The World,duzda, 41,#76,3.447,3.447,#113,3.220,3.220,#31,3.951,3.951,#105,3.171,3.171
Brave Wizard,Woomek, 15,#77,3.444,3.444,#84,3.467,3.467,#49,3.733,3.733,#109,3.133,3.133
Grow Up,Martin, 9,#77,3.444,3.444,#22,4.111,4.111,#177,2.667,2.667,#58,3.556,3.556
Grow Your Blob,Michel Fonseca, 45,#79,3.422,3.422,#57,3.711,3.711,#128,3.111,3.111,#69,3.444,3.444
Z-Burgers,oliguegames, 24,#80,3.417,3.417,#99,3.375,3.375,#123,3.167,3.167,#44,3.708,3.708
